Workbook

Sheet qsr_pos_logs_Uncleaned
A1: order_id | B1: store_id | C1: transaction_datetime | D1: business_day | E1: daypart | F1: service_mode | G1: menu_item | H1: modifier | I1: quantity | J1: unit_price | K1: discount | L1: tax | M1: total_amount | N1: payment_type
A2: 120000 | B2: 102 | C2: 45843.26 | D2: 45843 | E2: Breakfast | F2: Drive-Thru | G2: Bottled Water | I2: 1 | J2: 1.48 | K2: 0.15 | L2: 0.1 | M2: 1.43 | N2: Cash
A3: 120001 | B3: 201 | C3: 45843.492 | D3: 45843 | E3: Lunch | F3: Dine-In | G3: Chicken Sandwich | I3: 1 | J3: 5.34 | K3: 0 | L3: 0.45 | M3: 5.79 | N3: Card
A4: 120002 | B4: 403 | C4: 45760.337 | D4: 45760 | E4: Breakfast | F4: Takeout | G4: Bottled Water | H4: Light Ice | I4: 1 | J4: 1.49 | K4: 0.15 | L4: 0.1 | M4: 1.44 | N4: Cash
A5: 120003 | B5: 301 | C5: 45833.279 | D5: 45833 | E5: Breakfast | F5: Drive-Thru | G5: Egg Muffin | H5: No Cheese | I5: 1 | J5: 3.62 | K5: 0 | L5: 0.34 | M5: 3.96 | N5: Cash
A6: 120004 | B6: 301 | C6: 45870.541 | D6: 45870 | E6: Lunch | F6: Drive-Thru | G6: Spicy Chicken Combo | I6: 2 | J6: 9.17 | K6: 0 | L6: 1.38 | M6: 19.72 | N6: Card
A7: 120005 | B7: 501 | C7: 45850.523 | D7: 45850 | E7: Lunch | F7: Dine-In | G7: Double Cheeseburger | I7: 1 | J7: 5.64 | K7: 0 | L7: 0.37 | M7: 6.01 | N7: Card
A8: 120006 | B8: 101 | C8: 45864.748 | D8: 45864 | E8: Afternoon | F8: Delivery | G8: Onion Rings | I8: 1 | J8: 3.59 | K8: 0.54 | L8: 0.29 | M8: 3.34 | N8: MobilePay
A9: 120007 | B9: 403 | C9: 45859.7 | D9: 45859 | E9: Afternoon | F9: Takeout | G9: Soft Drink (Medium) | I9: 1 | J9: 1.8 | K9: 0.27 | L9: 0.11 | M9: 1.64 | N9: Cash
A10: 120008 | B10: 102 | C10: 45810.964 | D10: 45810 | E10: Late Night | F10: Delivery | G10: Chicken Sandwich | H10: Extra Sauce | I10: 2 | J10: 5.22 | K10: 0 | L10: 0.79 | M10: 11.73 | N10: Card
A11: 120009 | B11: 402 | C11: 45850.223 | D11: 45850 | E11: Breakfast | F11: Drive-Thru | G11: Hash Browns | I11: 1 | J11: 2 | K11: 0 | L11: 0.12 | M11: 2.12 | N11: Card
A12: 120010 | B12: 103 | C12: 45766.886 | D12: 45766 | E12: Dinner | F12: Takeout | G12: Double Cheeseburger | I12: 1 | J12: 5.55 | K12: 0 | L12: 0.33 | M12: 5.88 | N12: Card
A13: 120011 | B13: 102 | C13: 45854.464 | D13: 45854 | E13: Morning | F13: Dine-In | G13: Apple Pie | I13: 1 | J13: 1.53 | K13: 0 | L13: 0.1 | M13: 1.63 | N13: Card
A14: 120012 | B14: 201 | C14: 45816.343 | D14: 45816 | E14: Breakfast | F14: Takeout | G14: Sausage Biscuit | H14: Sausage Patty | I14: 2 | J14: 3.1 | K14: 0 | L14: 0.64 | M14: 9.24 | N14: Card
A15: 120013 | B15: 103 | C15: 45851.443 | D15: 45851 | E15: Morning | F15: Takeout | G15: Coffee | H15: Oat Milk | I15: 2 | J15: 1.51 | K15: 0 | L15: 0.27 | M15: 4.69 | N15: Cash
A16: 120014 | B16: 201 | C16: 45758.526 | D16: 45758 | E16: Lunch | F16: Dine-In | G16: Spicy Chicken Combo | I16: 1 | J16: 8.43 | K16: 0 | L16: 0.67 | M16: 9.1 | N16: Card
A17: 120015 | B17: 102 | C17: 45799.379 | D17: 45799 | E17: Breakfast | F17: Delivery | G17: Egg Muffin | I17: 1 | J17: 3.1 | K17: 0 | L17: 0.23 | M17: 3.33 | N17: Card
A18: 120016 | B18: 403 | C18: 45774.389 | D18: 45774 | E18: Breakfast | F18: Drive-Thru | G18: Egg Muffin | I18: 1 | J18: 2.99 | K18: 0 | L18: 0.22 | M18: 3.21 | N18: MobilePay
A19: 120017 | B19: 403 | C19: 45763.462 | D19: 45763 | E19: Lunch | F19: Takeout | G19: Cheeseburger | I19: 1 | J19: 4.59 | K19: 0 | M19: 5 | N19: Card
A20: 120018 | B20: 403 | C20: 45831.399 | D20: 45831 | E20: Breakfast | F20: Takeout | G20: Sausage Biscuit | H20: Extra Egg | I20: 2 | J20: 2.81 | K20: 0 | L20: 0.55 | M20: 8.17 | N20: Card
A21: 120019 | B21: 103 | C21: 45848.828 | D21: 45848 | E21: Dinner | F21: Dine-In | G21: Chicken Sandwich | H21: Extra Sauce | I21: 1 | J21: 4.87 | K21: 0 | L21: 0.37 | M21: 5.49 | N21: Card
A22: 120020 | B22: 201 | C22: 45761.474 | D22: 45761 | E22: Morning | F22: Drive-Thru | G22: Coffee | H22: Sugar-Free Syrup | I22: 1 | J22: 2.18 | K22: 0 | L22: 0.19 | M22: 2.67 | N22: MobilePay
A23: 120021 | B23: 101 | C23: 45845.276 | D23: 45845 | E23: Breakfast | F23: Dine-In | G23: Sausage Biscuit | H23: Cinnamon | I23: 1 | J23: 2.98 | K23: 0 | L23: 0.26 | M23: 3.34 | N23: Cash
A24: 120022 | B24: 403 | C24: 45758.741 | D24: 45758 | E24: Afternoon | F24: Dine-In | G24: Ice Cream Cone | H24: Cinnamon | I24: 1 | J24: 1.65 | K24: 0 | L24: 0.13 | M24: 1.88 | N24: Card
A25: 120023 | B25: 201 | C25: 45758.614 | D25: 45758 | E25: Lunch | F25: Drive-Thru | G25: Spicy Chicken Sandwich | H25: No Pickles | I25: 1 | J25: 5.09 | K25: 0 | L25: 0.41 | M25: 5.5 | N25: Cash
A26: 120024 | B26: 103 | C26: 45842.738 | D26: 45842 | E26: Afternoon | F26: Takeout | G26: Ice Cream Cone | I26: 1 | J26: 1.58 | K26: 0 | L26: 0.11 | M26: 1.69 | N26: Card
A27: 120025 | B27: 401 | C27: 45805.823 | D27: 45805 | E27: Dinner | F27: Takeout | G27: Chicken Sandwich | H27: Extra Cheese | I27: 1 | J27: 5.43 | K27: 0 | L27: 0.56 | M27: 6.49 | N27: Card
A28: 120026 | B28: 402 | C28: 45807.723 | D28: 45807 | E28: Afternoon | F28: Drive-Thru | G28: Milkshake | H28: Cinnamon | I28: 1 | J28: 3.61 | K28: 0 | L28: 0.33 | M28: 4.04 | N28: Cash
A29: 120027 | B29: 402 | C29: 45843.67 | D29: 45843 | E29: Afternoon | F29: Dine-In | G29: French Fries | H29: Small Size | I29: 1 | J29: 2.75 | K29: 0 | L29: 0.17 | M29: 2.62 | N29: Card
A30: 120028 | B30: 201 | C30: 45829.788 | D30: 45829 | E30: Dinner | F30: Drive-Thru | G30: Cheeseburger | I30: 1 | J30: 4.29 | K30: 0 | L30: 0.36 | M30: 4.65 | N30: Card
A31: 120029 | B31: 202 | C31: 45875.598 | D31: 45875 | E31: Lunch | F31: Delivery | G31: Chicken Sandwich | H31: No Onions | I31: 3 | J31: 5.28 | K31: 0 | L31: 1.35 | M31: 17.19 | N31: Card
A32: 120030 | B32: 103 | C32: 45830.301 | D32: 45830 | E32: Breakfast | F32: Takeout | G32: Sausage Biscuit | I32: 1 | J32: 2.89 | K32: 0.15 | L32: 0.27 | M32: 3.11 | N32: Cash
A33: 120031 | B33: 101 | C33: 45847.828 | D33: 45847 | E33: Dinner | F33: Delivery | G33: Cheeseburger Combo | I33: 2 | J33: 9.42 | K33: 0 | L33: 1.41 | M33: 20.25 | N33: Card
A34: 120032 | B34: 103 | C34: 45865.958 | D34: 45865 | E34: Late Night | F34: Drive-Thru | G34: Spicy Chicken Sandwich | I34: 1 | J34: 5.63 | K34: 0 | L34: 0.48 | M34: 7.11 | N34: MobilePay
A35: 120033 | B35: 501 | C35: 45834.904 | D35: 45834 | E35: Dinner | F35: Dine-In | G35: Cheeseburger | I35: 1 | J35: 4.14 | K35: 0 | L35: 0.33 | M35: 4.47 | N35: Cash
A36: 120034 | B36: 202 | C36: 45761.743 | D36: 45761 | E36: Afternoon | F36: Takeout | G36: Iced Tea | I36: 1 | J36: 2 | K36: 0 | L36: 0.15 | M36: 2.15 | N36: MobilePay
A37: 120035 | B37: 101 | C37: 45837.522 | D37: 45837 | E37: Lunch | F37: Takeout | G37: Chicken Sandwich | I37: 1 | J37: 4.94 | K37: 0 | L37: 0.43 | M37: 6.37 | N37: Card
A38: 120036 | B38: 402 | C38: 45876.471 | D38: 45876 | E38: Lunch | F38: Takeout | G38: Spicy Chicken Combo | I38: 1 | J38: 9.39 | K38: 0 | L38: 0.89 | M38: 10.28 | N38: Card
A39: 120037 | B39: 201 | C39: 45783.508 | D39: 45783 | E39: Lunch | F39: Drive-Thru | G39: Chicken Sandwich Combo | H39: Spicy | I39: 1 | J39: 8.01 | K39: 0 | L39: 0.58 | M39: 8.59 | N39: Card
A40: 120038 | B40: 101 | C40: 45808.031 | D40: 45808 | E40: Late Night | F40: Drive-Thru | G40: Cheeseburger | I40: 1 | J40: 4.05 | K40: 0 | L40: 0.32 | M40: 4.37 | N40: Cash
...

Sheet Cleaning
A1: Order_ID | B1: Store_ID | C1: Transaction_Date | D1: Time | E1: Business_Day | F1: Day_Of_Week | G1: Day_Part | H1: Service_Mode_ | I1: Service_Mode | J1: Menu_Item | K1: Modifier_ | L1: Modifier | M1: Quantity | N1: Unit Price | O1: Unit_Price | P1: Gross | Q1: Discount_ | R1: Discount | S1: Tax_ | T1: Tax | U1: Total Amount | V1: Total_Amount | W1: Payment Type | X1: Payment_type
A2: 120000 | B2: 102 | C2: 45843 | D2: 0.25981481 | E2: 45843 | F2: =TEXT(Table1[[#This Row],[Business_Day]],"dddd") -> Saturday | G2: Breakfast | H2: Drive-Thru | I2: =IF(H2="","Unknown",H2) -> Drive-Thru | J2: Bottled Water | L2: =IF(K2="","No Modifier",K2) -> No Modifier | M2: 1 | N2: 1.48 | O2: =(V2-T2+R2)/M2 -> 1.48 | P2: =PRODUCT(M2,O2) -> 1.48 | Q2: 0.15 | R2: =IF(ISBLANK(Q2),ROUND((M2*O2)+T2-V2,2),Q2) -> 0.15 | S2: 0.1 | T2: =IF(S2="",V2-P2+R2,S2) -> 0.1 | U2: 1.43 | V2: =IF(U2="",(M2*O2)-R2+T2,U2) -> 1.43 | W2: Cash | X2: =IF(W2="","Card",W2) -> Cash
A3: 120001 | B3: 201 | C3: 45843 | D3: 0.49225694 | E3: 45843 | F3: =TEXT(Table1[[#This Row],[Business_Day]],"dddd") -> Saturday | G3: Lunch | H3: Dine-In | I3: =IF(H3="","Unknown",H3) -> Dine-In | J3: Chicken Sandwich | L3: =IF(K3="","No Modifier",K3) -> No Modifier | M3: 1 | N3: 5.34 | O3: =(V3-T3+R3)/M3 -> 5.34 | P3: =PRODUCT(M3,O3) -> 5.34 | Q3: 0 | R3: =IF(ISBLANK(Q3),ROUND((M3*O3)+T3-V3,2),Q3) -> 0 | S3: 0.45 | T3: =IF(S3="",V3-P3+R3,S3) -> 0.45 | U3: 5.79 | V3: =IF(U3="",(M3*O3)-R3+T3,U3) -> 5.79 | W3: Card | X3: =IF(W3="","Card",W3) -> Card
A4: 120002 | B4: 403 | C4: 45760 | D4: 0.33721065 | E4: 45760 | F4: =TEXT(Table1[[#This Row],[Business_Day]],"dddd") -> Sunday | G4: Breakfast | H4: Takeout | I4: =IF(H4="","Unknown",H4) -> Takeout | J4: Bottled Water | K4: Light Ice | L4: =IF(K4="","No Modifier",K4) -> Light Ice | M4: 1 | N4: 1.49 | O4: =(V4-T4+R4)/M4 -> 1.49 | P4: =PRODUCT(M4,O4) -> 1.49 | Q4: 0.15 | R4: =IF(ISBLANK(Q4),ROUND((M4*O4)+T4-V4,2),Q4) -> 0.15 | S4: 0.1 | T4: =IF(S4="",V4-P4+R4,S4) -> 0.1 | U4: 1.44 | V4: =IF(U4="",(M4*O4)-R4+T4,U4) -> 1.44 | W4: Cash | X4: =IF(W4="","Card",W4) -> Cash | Z4: Row Labels | AA4: Sum of Total_Amount
A5: 120003 | B5: 301 | C5: 45833 | D5: 0.27936343 | E5: 45833 | F5: =TEXT(Table1[[#This Row],[Business_Day]],"dddd") -> Wednesday | G5: Breakfast | H5: Drive-Thru | I5: =IF(H5="","Unknown",H5) -> Drive-Thru | J5: Egg Muffin | K5: No Cheese | L5: =IF(K5="","No Modifier",K5) -> No Cheese | M5: 1 | N5: 3.62 | O5: =(V5-T5+R5)/M5 -> 3.62 | P5: =PRODUCT(M5,O5) -> 3.62 | Q5: 0 | R5: =IF(ISBLANK(Q5),ROUND((M5*O5)+T5-V5,2),Q5) -> 0 | S5: 0.34 | T5: =IF(S5="",V5-P5+R5,S5) -> 0.34 | U5: 3.96 | V5: =IF(U5="",(M5*O5)-R5+T5,U5) -> 3.96 | W5: Cash | X5: =IF(W5="","Card",W5) -> Cash | Z5: Card | AA5: 6648.29
A6: 120004 | B6: 301 | C6: 45870 | D6: 0.54069444 | E6: 45870 | F6: =TEXT(Table1[[#This Row],[Business_Day]],"dddd") -> Friday | G6: Lunch | H6: Drive-Thru | I6: =IF(H6="","Unknown",H6) -> Drive-Thru | J6: Spicy Chicken Combo | L6: =IF(K6="","No Modifier",K6) -> No Modifier | M6: 2 | N6: 9.17 | O6: =(V6-T6+R6)/M6 -> 9.17 | P6: =PRODUCT(M6,O6) -> 18.34 | Q6: 0 | R6: =IF(ISBLANK(Q6),ROUND((M6*O6)+T6-V6,2),Q6) -> 0 | S6: 1.38 | T6: =IF(S6="",V6-P6+R6,S6) -> 1.38 | U6: 19.72 | V6: =IF(U6="",(M6*O6)-R6+T6,U6) -> 19.72 | W6: Card | X6: =IF(W6="","Card",W6) -> Card | Z6: Cash | AA6: 2339.22
A7: 120005 | B7: 501 | C7: 45850 | D7: 0.52258102 | E7: 45850 | F7: =TEXT(Table1[[#This Row],[Business_Day]],"dddd") -> Saturday | G7: Lunch | H7: Dine-In | I7: =IF(H7="","Unknown",H7) -> Dine-In | J7: Double Cheeseburger | L7: =IF(K7="","No Modifier",K7) -> No Modifier | M7: 1 | N7: 5.64 | O7: =(V7-T7+R7)/M7 -> 5.64 | P7: =PRODUCT(M7,O7) -> 5.64 | Q7: 0 | R7: =IF(ISBLANK(Q7),ROUND((M7*O7)+T7-V7,2),Q7) -> 0 | S7: 0.37 | T7: =IF(S7="",V7-P7+R7,S7) -> 0.37 | U7: 6.01 | V7: =IF(U7="",(M7*O7)-R7+T7,U7) -> 6.01 | W7: Card | X7: =IF(W7="","Card",W7) -> Card | Z7: GiftCard | AA7: 645.21
A8: 120006 | B8: 101 | C8: 45864 | D8: 0.24761574 | E8: 45864 | F8: =TEXT(Table1[[#This Row],[Business_Day]],"dddd") -> Saturday | G8: Afternoon | H8: Delivery | I8: =IF(H8="","Unknown",H8) -> Delivery | J8: Onion Rings | L8: =IF(K8="","No Modifier",K8) -> No Modifier | M8: 1 | N8: 3.59 | O8: =(V8-T8+R8)/M8 -> 3.59 | P8: =PRODUCT(M8,O8) -> 3.59 | Q8: 0.54 | R8: =IF(ISBLANK(Q8),ROUND((M8*O8)+T8-V8,2),Q8) -> 0.54 | S8: 0.29 | T8: =IF(S8="",V8-P8+R8,S8) -> 0.29 | U8: 3.34 | V8: =IF(U8="",(M8*O8)-R8+T8,U8) -> 3.34 | W8: MobilePay | X8: =IF(W8="","Card",W8) -> MobilePay | Z8: MobilePay | AA8: 1698.02
A9: 120007 | B9: 403 | C9: 45859 | D9: 0.20011574 | E9: 45859 | F9: =TEXT(Table1[[#This Row],[Business_Day]],"dddd") -> Monday | G9: Afternoon | H9: Takeout | I9: =IF(H9="","Unknown",H9) -> Takeout | J9: Soft Drink (Medium) | L9: =IF(K9="","No Modifier",K9) -> No Modifier | M9: 1 | N9: 1.8 | O9: =(V9-T9+R9)/M9 -> 1.8 | P9: =PRODUCT(M9,O9) -> 1.8 | Q9: 0.27 | R9: =IF(ISBLANK(Q9),ROUND((M9*O9)+T9-V9,2),Q9) -> 0.27 | S9: 0.11 | T9: =IF(S9="",V9-P9+R9,S9) -> 0.11 | U9: 1.64 | V9: =IF(U9="",(M9*O9)-R9+T9,U9) -> 1.64 | W9: Cash | X9: =IF(W9="","Card",W9) -> Cash | Z9: (blank) | AA9: 310.9
A10: 120008 | B10: 102 | C10: 45810 | D10: 0.464375 | E10: 45810 | F10: =TEXT(Table1[[#This Row],[Business_Day]],"dddd") -> Monday | G10: Late Night | H10: Delivery | I10: =IF(H10="","Unknown",H10) -> Delivery | J10: Chicken Sandwich | K10: Extra Sauce | L10: =IF(K10="","No Modifier",K10) -> Extra Sauce | M10: 2 | N10: 5.22 | O10: =(V10-T10+R10)/M10 -> 5.47 | P10: =PRODUCT(M10,O10) -> 10.94 | Q10: 0 | R10: =IF(ISBLANK(Q10),ROUND((M10*O10)+T10-V10,2),Q10) -> 0 | S10: 0.79 | T10: =IF(S10="",V10-P10+R10,S10) -> 0.79 | U10: 11.73 | V10: =IF(U10="",(M10*O10)-R10+T10,U10) -> 11.73 | W10: Card | X10: =IF(W10="","Card",W10) -> Card | Z10: Grand Total | AA10: 11641.64
A11: 120009 | B11: 402 | C11: 45850 | D11: 0.22292824 | E11: 45850 | F11: =TEXT(Table1[[#This Row],[Business_Day]],"dddd") -> Saturday | G11: Breakfast | H11: Drive-Thru | I11: =IF(H11="","Unknown",H11) -> Drive-Thru | J11: Hash Browns | L11: =IF(K11="","No Modifier",K11) -> No Modifier | M11: 1 | N11: 2 | O11: =(V11-T11+R11)/M11 -> 2 | P11: =PRODUCT(M11,O11) -> 2 | Q11: 0 | R11: =IF(ISBLANK(Q11),ROUND((M11*O11)+T11-V11,2),Q11) -> 0 | S11: 0.12 | T11: =IF(S11="",V11-P11+R11,S11) -> 0.12 | U11: 2.12 | V11: =IF(U11="",(M11*O11)-R11+T11,U11) -> 2.12 | W11: Card | X11: =IF(W11="","Card",W11) -> Card
A12: 120010 | B12: 103 | C12: 45766 | D12: 0.38599537 | E12: 45766 | F12: =TEXT(Table1[[#This Row],[Business_Day]],"dddd") -> Saturday | G12: Dinner | H12: Takeout | I12: =IF(H12="","Unknown",H12) -> Takeout | J12: Double Cheeseburger | L12: =IF(K12="","No Modifier",K12) -> No Modifier | M12: 1 | N12: 5.55 | O12: =(V12-T12+R12)/M12 -> 5.55 | P12: =PRODUCT(M12,O12) -> 5.55 | Q12: 0 | R12: =IF(ISBLANK(Q12),ROUND((M12*O12)+T12-V12,2),Q12) -> 0 | S12: 0.33 | T12: =IF(S12="",V12-P12+R12,S12) -> 0.33 | U12: 5.88 | V12: =IF(U12="",(M12*O12)-R12+T12,U12) -> 5.88 | W12: Card | X12: =IF(W12="","Card",W12) -> Card
A13: 120011 | B13: 102 | C13: 45854 | D13: 0.46420139 | E13: 45854 | F13: =TEXT(Table1[[#This Row],[Business_Day]],"dddd") -> Wednesday | G13: Morning | H13: Dine-In | I13: =IF(H13="","Unknown",H13) -> Dine-In | J13: Apple Pie | L13: =IF(K13="","No Modifier",K13) -> No Modifier | M13: 1 | N13: 1.53 | O13: =(V13-T13+R13)/M13 -> 1.53 | P13: =PRODUCT(M13,O13) -> 1.53 | Q13: 0 | R13: =IF(ISBLANK(Q13),ROUND((M13*O13)+T13-V13,2),Q13) -> 0 | S13: 0.1 | T13: =IF(S13="",V13-P13+R13,S13) -> 0.1 | U13: 1.63 | V13: =IF(U13="",(M13*O13)-R13+T13,U13) -> 1.63 | W13: Card | X13: =IF(W13="","Card",W13) -> Card
A14: 120012 | B14: 201 | C14: 45816 | D14: 0.34299769 | E14: 45816 | F14: =TEXT(Table1[[#This Row],[Business_Day]],"dddd") -> Sunday | G14: Breakfast | H14: Takeout | I14: =IF(H14="","Unknown",H14) -> Takeout | J14: Sausage Biscuit | K14: Sausage Patty | L14: =IF(K14="","No Modifier",K14) -> Sausage Patty | M14: 2 | N14: 3.1 | O14: =(V14-T14+R14)/M14 -> 4.3 | P14: =PRODUCT(M14,O14) -> 8.6 | Q14: 0 | R14: =IF(ISBLANK(Q14),ROUND((M14*O14)+T14-V14,2),Q14) -> 0 | S14: 0.64 | T14: =IF(S14="",V14-P14+R14,S14) -> 0.64 | U14: 9.24 | V14: =IF(U14="",(M14*O14)-R14+T14,U14) -> 9.24 | W14: Card | X14: =IF(W14="","Card",W14) -> Card
A15: 120013 | B15: 103 | C15: 45851 | D15: 0.44290509 | E15: 45851 | F15: =TEXT(Table1[[#This Row],[Business_Day]],"dddd") -> Sunday | G15: Morning | H15: Takeout | I15: =IF(H15="","Unknown",H15) -> Takeout | J15: Coffee | K15: Oat Milk | L15: =IF(K15="","No Modifier",K15) -> Oat Milk | M15: 2 | N15: 1.51 | O15: =(V15-T15+R15)/M15 -> 2.21 | P15: =PRODUCT(M15,O15) -> 4.42 | Q15: 0 | R15: =IF(ISBLANK(Q15),ROUND((M15*O15)+T15-V15,2),Q15) -> 0 | S15: 0.27 | T15: =IF(S15="",V15-P15+R15,S15) -> 0.27 | U15: 4.69 | V15: =IF(U15="",(M15*O15)-R15+T15,U15) -> 4.69 | W15: Cash | X15: =IF(W15="","Card",W15) -> Cash
A16: 120014 | B16: 201 | C16: 45758 | D16: 0.52613426 | E16: 45758 | F16: =TEXT(Table1[[#This Row],[Business_Day]],"dddd") -> Friday | G16: Lunch | H16: Dine-In | I16: =IF(H16="","Unknown",H16) -> Dine-In | J16: Spicy Chicken Combo | L16: =IF(K16="","No Modifier",K16) -> No Modifier | M16: 1 | N16: 8.43 | O16: =(V16-T16+R16)/M16 -> 8.43 | P16: =PRODUCT(M16,O16) -> 8.43 | Q16: 0 | R16: =IF(ISBLANK(Q16),ROUND((M16*O16)+T16-V16,2),Q16) -> 0 | S16: 0.67 | T16: =IF(S16="",V16-P16+R16,S16) -> 0.67 | U16: 9.1 | V16: =IF(U16="",(M16*O16)-R16+T16,U16) -> 9.1 | W16: Card | X16: =IF(W16="","Card",W16) -> Card
A17: 120015 | B17: 102 | C17: 45799 | D17: 0.37921296 | E17: 45799 | F17: =TEXT(Table1[[#This Row],[Business_Day]],"dddd") -> Thursday | G17: Breakfast | H17: Delivery | I17: =IF(H17="","Unknown",H17) -> Delivery | J17: Egg Muffin | L17: =IF(K17="","No Modifier",K17) -> No Modifier | M17: 1 | N17: 3.1 | O17: =(V17-T17+R17)/M17 -> 3.1 | P17: =PRODUCT(M17,O17) -> 3.1 | Q17: 0 | R17: =IF(ISBLANK(Q17),ROUND((M17*O17)+T17-V17,2),Q17) -> 0 | S17: 0.23 | T17: =IF(S17="",V17-P17+R17,S17) -> 0.23 | U17: 3.33 | V17: =IF(U17="",(M17*O17)-R17+T17,U17) -> 3.33 | W17: Card | X17: =IF(W17="","Card",W17) -> Card
A18: 120016 | B18: 403 | C18: 45774 | D18: 0.38887731 | E18: 45774 | F18: =TEXT(Table1[[#This Row],[Business_Day]],"dddd") -> Sunday | G18: Breakfast | H18: Drive-Thru | I18: =IF(H18="","Unknown",H18) -> Drive-Thru | J18: Egg Muffin | L18: =IF(K18="","No Modifier",K18) -> No Modifier | M18: 1 | N18: 2.99 | O18: =(V18-T18+R18)/M18 -> 2.99 | P18: =PRODUCT(M18,O18) -> 2.99 | Q18: 0 | R18: =IF(ISBLANK(Q18),ROUND((M18*O18)+T18-V18,2),Q18) -> 0 | S18: 0.22 | T18: =IF(S18="",V18-P18+R18,S18) -> 0.22 | U18: 3.21 | V18: =IF(U18="",(M18*O18)-R18+T18,U18) -> 3.21 | W18: MobilePay | X18: =IF(W18="","Card",W18) -> MobilePay
A19: 120017 | B19: 403 | C19: 45763 | D19: 0.46226852 | E19: 45763 | F19: =TEXT(Table1[[#This Row],[Business_Day]],"dddd") -> Wednesday | G19: Lunch | H19: Takeout | I19: =IF(H19="","Unknown",H19) -> Takeout | J19: Cheeseburger | L19: =IF(K19="","No Modifier",K19) -> No Modifier | M19: 1 | N19: 4.59 | O19: =(V19-T19+R19)/M19 -> 5 | P19: =PRODUCT(M19,O19) -> 5 | Q19: 0 | R19: =IF(ISBLANK(Q19),ROUND((M19*O19)+T19-V19,2),Q19) -> 0 | T19: =IF(S19="",V19-P19+R19,S19) -> 0 | U19: 5 | V19: =IF(U19="",(M19*O19)-R19+T19,U19) -> 5 | W19: Card | X19: =IF(W19="","Card",W19) -> Card
A20: 120018 | B20: 403 | C20: 45831 | D20: 0.39940972 | E20: 45831 | F20: =TEXT(Table1[[#This Row],[Business_Day]],"dddd") -> Monday | G20: Breakfast | H20: Takeout | I20: =IF(H20="","Unknown",H20) -> Takeout | J20: Sausage Biscuit | K20: Extra Egg | L20: =IF(K20="","No Modifier",K20) -> Extra Egg | M20: 2 | N20: 2.81 | O20: =(V20-T20+R20)/M20 -> 3.81 | P20: =PRODUCT(M20,O20) -> 7.62 | Q20: 0 | R20: =IF(ISBLANK(Q20),ROUND((M20*O20)+T20-V20,2),Q20) -> 0 | S20: 0.55 | T20: =IF(S20="",V20-P20+R20,S20) -> 0.55 | U20: 8.17 | V20: =IF(U20="",(M20*O20)-R20+T20,U20) -> 8.17 | W20: Card | X20: =IF(W20="","Card",W20) -> Card
A21: 120019 | B21: 103 | C21: 45848 | D21: 0.32767361 | E21: 45848 | F21: =TEXT(Table1[[#This Row],[Business_Day]],"dddd") -> Thursday | G21: Dinner | H21: Dine-In | I21: =IF(H21="","Unknown",H21) -> Dine-In | J21: Chicken Sandwich | K21: Extra Sauce | L21: =IF(K21="","No Modifier",K21) -> Extra Sauce | M21: 1 | N21: 4.87 | O21: =(V21-T21+R21)/M21 -> 5.12 | P21: =PRODUCT(M21,O21) -> 5.12 | Q21: 0 | R21: =IF(ISBLANK(Q21),ROUND((M21*O21)+T21-V21,2),Q21) -> 0 | S21: 0.37 | T21: =IF(S21="",V21-P21+R21,S21) -> 0.37 | U21: 5.49 | V21: =IF(U21="",(M21*O21)-R21+T21,U21) -> 5.49 | W21: Card | X21: =IF(W21="","Card",W21) -> Card
A22: 120020 | B22: 201 | C22: 45761 | D22: 0.47383102 | E22: 45761 | F22: =TEXT(Table1[[#This Row],[Business_Day]],"dddd") -> Monday | G22: Morning | H22: Drive-Thru | I22: =IF(H22="","Unknown",H22) -> Drive-Thru | J22: Coffee | K22: Sugar-Free Syrup | L22: =IF(K22="","No Modifier",K22) -> Sugar-Free Syrup | M22: 1 | N22: 2.18 | O22: =(V22-T22+R22)/M22 -> 2.48 | P22: =PRODUCT(M22,O22) -> 2.48 | Q22: 0 | R22: =IF(ISBLANK(Q22),ROUND((M22*O22)+T22-V22,2),Q22) -> 0 | S22: 0.19 | T22: =IF(S22="",V22-P22+R22,S22) -> 0.19 | U22: 2.67 | V22: =IF(U22="",(M22*O22)-R22+T22,U22) -> 2.67 | W22: MobilePay | X22: =IF(W22="","Card",W22) -> MobilePay
A23: 120021 | B23: 101 | C23: 45845 | D23: 0.27587963 | E23: 45845 | F23: =TEXT(Table1[[#This Row],[Business_Day]],"dddd") -> Monday | G23: Breakfast | H23: Dine-In | I23: =IF(H23="","Unknown",H23) -> Dine-In | J23: Sausage Biscuit | K23: Cinnamon | L23: =IF(K23="","No Modifier",K23) -> Cinnamon | M23: 1 | N23: 2.98 | O23: =(V23-T23+R23)/M23 -> 3.08 | P23: =PRODUCT(M23,O23) -> 3.08 | Q23: 0 | R23: =IF(ISBLANK(Q23),ROUND((M23*O23)+T23-V23,2),Q23) -> 0 | S23: 0.26 | T23: =IF(S23="",V23-P23+R23,S23) -> 0.26 | U23: 3.34 | V23: =IF(U23="",(M23*O23)-R23+T23,U23) -> 3.34 | W23: Cash | X23: =IF(W23="","Card",W23) -> Cash
A24: 120022 | B24: 403 | C24: 45758 | D24: 0.24145833 | E24: 45758 | F24: =TEXT(Table1[[#This Row],[Business_Day]],"dddd") -> Friday | G24: Afternoon | H24: Dine-In | I24: =IF(H24="","Unknown",H24) -> Dine-In | J24: Ice Cream Cone | K24: Cinnamon | L24: =IF(K24="","No Modifier",K24) -> Cinnamon | M24: 1 | N24: 1.65 | O24: =(V24-T24+R24)/M24 -> 1.75 | P24: =PRODUCT(M24,O24) -> 1.75 | Q24: 0 | R24: =IF(ISBLANK(Q24),ROUND((M24*O24)+T24-V24,2),Q24) -> 0 | S24: 0.13 | T24: =IF(S24="",V24-P24+R24,S24) -> 0.13 | U24: 1.88 | V24: =IF(U24="",(M24*O24)-R24+T24,U24) -> 1.88 | W24: Card | X24: =IF(W24="","Card",W24) -> Card
A25: 120023 | B25: 201 | C25: 45758 | D25: 0.11373843 | E25: 45758 | F25: =TEXT(Table1[[#This Row],[Business_Day]],"dddd") -> Friday | G25: Lunch | H25: Drive-Thru | I25: =IF(H25="","Unknown",H25) -> Drive-Thru | J25: Spicy Chicken Sandwich | K25: No Pickles | L25: =IF(K25="","No Modifier",K25) -> No Pickles | M25: 1 | N25: 5.09 | O25: =(V25-T25+R25)/M25 -> 5.09 | P25: =PRODUCT(M25,O25) -> 5.09 | Q25: 0 | R25: =IF(ISBLANK(Q25),ROUND((M25*O25)+T25-V25,2),Q25) -> 0 | S25: 0.41 | T25: =IF(S25="",V25-P25+R25,S25) -> 0.41 | U25: 5.5 | V25: =IF(U25="",(M25*O25)-R25+T25,U25) -> 5.5 | W25: Cash | X25: =IF(W25="","Card",W25) -> Cash
A26: 120024 | B26: 103 | C26: 45842 | D26: 0.23796296 | E26: 45842 | F26: =TEXT(Table1[[#This Row],[Business_Day]],"dddd") -> Friday | G26: Afternoon | H26: Takeout | I26: =IF(H26="","Unknown",H26) -> Takeout | J26: Ice Cream Cone | L26: =IF(K26="","No Modifier",K26) -> No Modifier | M26: 1 | N26: 1.58 | O26: =(V26-T26+R26)/M26 -> 1.58 | P26: =PRODUCT(M26,O26) -> 1.58 | Q26: 0 | R26: =IF(ISBLANK(Q26),ROUND((M26*O26)+T26-V26,2),Q26) -> 0 | S26: 0.11 | T26: =IF(S26="",V26-P26+R26,S26) -> 0.11 | U26: 1.69 | V26: =IF(U26="",(M26*O26)-R26+T26,U26) -> 1.69 | W26: Card | X26: =IF(W26="","Card",W26) -> Card
A27: 120025 | B27: 401 | C27: 45805 | D27: 0.32342593 | E27: 45805 | F27: =TEXT(Table1[[#This Row],[Business_Day]],"dddd") -> Wednesday | G27: Dinner | H27: Takeout | I27: =IF(H27="","Unknown",H27) -> Takeout | J27: Chicken Sandwich | K27: Extra Cheese | L27: =IF(K27="","No Modifier",K27) -> Extra Cheese | M27: 1 | N27: 5.43 | O27: =(V27-T27+R27)/M27 -> 5.93 | P27: =PRODUCT(M27,O27) -> 5.93 | Q27: 0 | R27: =IF(ISBLANK(Q27),ROUND((M27*O27)+T27-V27,2),Q27) -> 0 | S27: 0.56 | T27: =IF(S27="",V27-P27+R27,S27) -> 0.56 | U27: 6.49 | V27: =IF(U27="",(M27*O27)-R27+T27,U27) -> 6.49 | W27: Card | X27: =IF(W27="","Card",W27) -> Card
A28: 120026 | B28: 402 | C28: 45807 | D28: 0.22277778 | E28: 45807 | F28: =TEXT(Table1[[#This Row],[Business_Day]],"dddd") -> Friday | G28: Afternoon | H28: Drive-Thru | I28: =IF(H28="","Unknown",H28) -> Drive-Thru | J28: Milkshake | K28: Cinnamon | L28: =IF(K28="","No Modifier",K28) -> Cinnamon | M28: 1 | N28: 3.61 | O28: =(V28-T28+R28)/M28 -> 3.71 | P28: =PRODUCT(M28,O28) -> 3.71 | Q28: 0 | R28: =IF(ISBLANK(Q28),ROUND((M28*O28)+T28-V28,2),Q28) -> 0 | S28: 0.33 | T28: =IF(S28="",V28-P28+R28,S28) -> 0.33 | U28: 4.04 | V28: =IF(U28="",(M28*O28)-R28+T28,U28) -> 4.04 | W28: Cash | X28: =IF(W28="","Card",W28) -> Cash
A29: 120027 | B29: 402 | C29: 45843 | D29: 0.16996528 | E29: 45843 | F29: =TEXT(Table1[[#This Row],[Business_Day]],"dddd") -> Saturday | G29: Afternoon | H29: Dine-In | I29: =IF(H29="","Unknown",H29) -> Dine-In | J29: French Fries | K29: Small Size | L29: =IF(K29="","No Modifier",K29) -> Small Size | M29: 1 | N29: 2.75 | O29: =(V29-T29+R29)/M29 -> 2.45 | P29: =PRODUCT(M29,O29) -> 2.45 | Q29: 0 | R29: =IF(ISBLANK(Q29),ROUND((M29*O29)+T29-V29,2),Q29) -> 0 | S29: 0.17 | T29: =IF(S29="",V29-P29+R29,S29) -> 0.17 | U29: 2.62 | V29: =IF(U29="",(M29*O29)-R29+T29,U29) -> 2.62 | W29: Card | X29: =IF(W29="","Card",W29) -> Card
A30: 120028 | B30: 201 | C30: 45829 | D30: 0.28814815 | E30: 45829 | F30: =TEXT(Table1[[#This Row],[Business_Day]],"dddd") -> Saturday | G30: Dinner | H30: Drive-Thru | I30: =IF(H30="","Unknown",H30) -> Drive-Thru | J30: Cheeseburger | L30: =IF(K30="","No Modifier",K30) -> No Modifier | M30: 1 | N30: 4.29 | O30: =(V30-T30+R30)/M30 -> 4.29 | P30: =PRODUCT(M30,O30) -> 4.29 | Q30: 0 | R30: =IF(ISBLANK(Q30),ROUND((M30*O30)+T30-V30,2),Q30) -> 0 | S30: 0.36 | T30: =IF(S30="",V30-P30+R30,S30) -> 0.36 | U30: 4.65 | V30: =IF(U30="",(M30*O30)-R30+T30,U30) -> 4.65 | W30: Card | X30: =IF(W30="","Card",W30) -> Card
A31: 120029 | B31: 202 | C31: 45875 | D31: 0.098402778 | E31: 45875 | F31: =TEXT(Table1[[#This Row],[Business_Day]],"dddd") -> Wednesday | G31: Lunch | H31: Delivery | I31: =IF(H31="","Unknown",H31) -> Delivery | J31: Chicken Sandwich | K31: No Onions | L31: =IF(K31="","No Modifier",K31) -> No Onions | M31: 3 | N31: 5.28 | O31: =(V31-T31+R31)/M31 -> 5.28 | P31: =PRODUCT(M31,O31) -> 15.84 | Q31: 0 | R31: =IF(ISBLANK(Q31),ROUND((M31*O31)+T31-V31,2),Q31) -> 0 | S31: 1.35 | T31: =IF(S31="",V31-P31+R31,S31) -> 1.35 | U31: 17.19 | V31: =IF(U31="",(M31*O31)-R31+T31,U31) -> 17.19 | W31: Card | X31: =IF(W31="","Card",W31) -> Card
A32: 120030 | B32: 103 | C32: 45830 | D32: 0.30103009 | E32: 45830 | F32: =TEXT(Table1[[#This Row],[Business_Day]],"dddd") -> Sunday | G32: Breakfast | H32: Takeout | I32: =IF(H32="","Unknown",H32) -> Takeout | J32: Sausage Biscuit | L32: =IF(K32="","No Modifier",K32) -> No Modifier | M32: 1 | N32: 2.89 | O32: =(V32-T32+R32)/M32 -> 2.99 | P32: =PRODUCT(M32,O32) -> 2.99 | Q32: 0.15 | R32: =IF(ISBLANK(Q32),ROUND((M32*O32)+T32-V32,2),Q32) -> 0.15 | S32: 0.27 | T32: =IF(S32="",V32-P32+R32,S32) -> 0.27 | U32: 3.11 | V32: =IF(U32="",(M32*O32)-R32+T32,U32) -> 3.11 | W32: Cash | X32: =IF(W32="","Card",W32) -> Cash
A33: 120031 | B33: 101 | C33: 45847 | D33: 0.3284838 | E33: 45847 | F33: =TEXT(Table1[[#This Row],[Business_Day]],"dddd") -> Wednesday | G33: Dinner | H33: Delivery | I33: =IF(H33="","Unknown",H33) -> Delivery | J33: Cheeseburger Combo | L33: =IF(K33="","No Modifier",K33) -> No Modifier | M33: 2 | N33: 9.42 | O33: =(V33-T33+R33)/M33 -> 9.42 | P33: =PRODUCT(M33,O33) -> 18.84 | Q33: 0 | R33: =IF(ISBLANK(Q33),ROUND((M33*O33)+T33-V33,2),Q33) -> 0 | S33: 1.41 | T33: =IF(S33="",V33-P33+R33,S33) -> 1.41 | U33: 20.25 | V33: =IF(U33="",(M33*O33)-R33+T33,U33) -> 20.25 | W33: Card | X33: =IF(W33="","Card",W33) -> Card
A34: 120032 | B34: 103 | C34: 45865 | D34: 0.4578588 | E34: 45865 | F34: =TEXT(Table1[[#This Row],[Business_Day]],"dddd") -> Sunday | G34: Late Night | H34: Drive-Thru | I34: =IF(H34="","Unknown",H34) -> Drive-Thru | J34: Spicy Chicken Sandwich | L34: =IF(K34="","No Modifier",K34) -> No Modifier | M34: 1 | N34: 5.63 | O34: =(V34-T34+R34)/M34 -> 6.63 | P34: =PRODUCT(M34,O34) -> 6.63 | Q34: 0 | R34: =IF(ISBLANK(Q34),ROUND((M34*O34)+T34-V34,2),Q34) -> 0 | S34: 0.48 | T34: =IF(S34="",V34-P34+R34,S34) -> 0.48 | U34: 7.11 | V34: =IF(U34="",(M34*O34)-R34+T34,U34) -> 7.11 | W34: MobilePay | X34: =IF(W34="","Card",W34) -> MobilePay
A35: 120033 | B35: 501 | C35: 45834 | D35: 0.40443287 | E35: 45834 | F35: =TEXT(Table1[[#This Row],[Business_Day]],"dddd") -> Thursday | G35: Dinner | H35: Dine-In | I35: =IF(H35="","Unknown",H35) -> Dine-In | J35: Cheeseburger | L35: =IF(K35="","No Modifier",K35) -> No Modifier | M35: 1 | N35: 4.14 | O35: =(V35-T35+R35)/M35 -> 4.14 | P35: =PRODUCT(M35,O35) -> 4.14 | Q35: 0 | R35: =IF(ISBLANK(Q35),ROUND((M35*O35)+T35-V35,2),Q35) -> 0 | S35: 0.33 | T35: =IF(S35="",V35-P35+R35,S35) -> 0.33 | U35: 4.47 | V35: =IF(U35="",(M35*O35)-R35+T35,U35) -> 4.47 | W35: Cash | X35: =IF(W35="","Card",W35) -> Cash
A36: 120034 | B36: 202 | C36: 45761 | D36: 0.24270833 | E36: 45761 | F36: =TEXT(Table1[[#This Row],[Business_Day]],"dddd") -> Monday | G36: Afternoon | H36: Takeout | I36: =IF(H36="","Unknown",H36) -> Takeout | J36: Iced Tea | L36: =IF(K36="","No Modifier",K36) -> No Modifier | M36: 1 | N36: 2 | O36: =(V36-T36+R36)/M36 -> 2 | P36: =PRODUCT(M36,O36) -> 2 | Q36: 0 | R36: =IF(ISBLANK(Q36),ROUND((M36*O36)+T36-V36,2),Q36) -> 0 | S36: 0.15 | T36: =IF(S36="",V36-P36+R36,S36) -> 0.15 | U36: 2.15 | V36: =IF(U36="",(M36*O36)-R36+T36,U36) -> 2.15 | W36: MobilePay | X36: =IF(W36="","Card",W36) -> MobilePay
A37: 120035 | B37: 101 | C37: 45837 | D37: 0.52167824 | E37: 45837 | F37: =TEXT(Table1[[#This Row],[Business_Day]],"dddd") -> Sunday | G37: Lunch | H37: Takeout | I37: =IF(H37="","Unknown",H37) -> Takeout | J37: Chicken Sandwich | L37: =IF(K37="","No Modifier",K37) -> No Modifier | M37: 1 | N37: 4.94 | O37: =(V37-T37+R37)/M37 -> 5.94 | P37: =PRODUCT(M37,O37) -> 5.94 | Q37: 0 | R37: =IF(ISBLANK(Q37),ROUND((M37*O37)+T37-V37,2),Q37) -> 0 | S37: 0.43 | T37: =IF(S37="",V37-P37+R37,S37) -> 0.43 | U37: 6.37 | V37: =IF(U37="",(M37*O37)-R37+T37,U37) -> 6.37 | W37: Card | X37: =IF(W37="","Card",W37) -> Card
A38: 120036 | B38: 402 | C38: 45876 | D38: 0.47099537 | E38: 45876 | F38: =TEXT(Table1[[#This Row],[Business_Day]],"dddd") -> Thursday | G38: Lunch | H38: Takeout | I38: =IF(H38="","Unknown",H38) -> Takeout | J38: Spicy Chicken Combo | L38: =IF(K38="","No Modifier",K38) -> No Modifier | M38: 1 | N38: 9.39 | O38: =(V38-T38+R38)/M38 -> 9.39 | P38: =PRODUCT(M38,O38) -> 9.39 | Q38: 0 | R38: =IF(ISBLANK(Q38),ROUND((M38*O38)+T38-V38,2),Q38) -> 0 | S38: 0.89 | T38: =IF(S38="",V38-P38+R38,S38) -> 0.89 | U38: 10.28 | V38: =IF(U38="",(M38*O38)-R38+T38,U38) -> 10.28 | W38: Card | X38: =IF(W38="","Card",W38) -> Card
A39: 120037 | B39: 201 | C39: 45783 | D39: 0.5084838 | E39: 45783 | F39: =TEXT(Table1[[#This Row],[Business_Day]],"dddd") -> Tuesday | G39: Lunch | H39: Drive-Thru | I39: =IF(H39="","Unknown",H39) -> Drive-Thru | J39: Chicken Sandwich Combo | K39: Spicy | L39: =IF(K39="","No Modifier",K39) -> Spicy | M39: 1 | N39: 8.01 | O39: =(V39-T39+R39)/M39 -> 8.01 | P39: =PRODUCT(M39,O39) -> 8.01 | Q39: 0 | R39: =IF(ISBLANK(Q39),ROUND((M39*O39)+T39-V39,2),Q39) -> 0 | S39: 0.58 | T39: =IF(S39="",V39-P39+R39,S39) -> 0.58 | U39: 8.59 | V39: =IF(U39="",(M39*O39)-R39+T39,U39) -> 8.59 | W39: Card | X39: =IF(W39="","Card",W39) -> Card
A40: 120038 | B40: 101 | C40: 45808 | D40: 0.53064815 | E40: 45808 | F40: =TEXT(Table1[[#This Row],[Business_Day]],"dddd") -> Saturday | G40: Late Night | H40: Drive-Thru | I40: =IF(H40="","Unknown",H40) -> Drive-Thru | J40: Cheeseburger | L40: =IF(K40="","No Modifier",K40) -> No Modifier | M40: 1 | N40: 4.05 | O40: =(V40-T40+R40)/M40 -> 4.05 | P40: =PRODUCT(M40,O40) -> 4.05 | Q40: 0 | R40: =IF(ISBLANK(Q40),ROUND((M40*O40)+T40-V40,2),Q40) -> 0 | S40: 0.32 | T40: =IF(S40="",V40-P40+R40,S40) -> 0.32 | U40: 4.37 | V40: =IF(U40="",(M40*O40)-R40+T40,U40) -> 4.37 | W40: Cash | X40: =IF(W40="","Card",W40) -> Cash
...

Sheet Cleaned
A1: Order_ID | B1: Store_ID | C1: Transaction_Date | D1: Time | E1: Business_Day | F1: Day_Of_Week | G1: Day_Part | H1: Service_Mode | I1: Menu_Item | J1: Modifier | K1: Payment_Type | L1: Quantity | M1: Unit_Price | N1: Gross_Amount | O1: Discount | P1: Tax | Q1: Total_Amount
A2: 120000 | B2: =_xlfn.XLOOKUP(A2,Cleaning!$A:$A,Cleaning!$B:$B,0,0) -> 102 | C2: =_xlfn.XLOOKUP(A2,Cleaning!$A:$A,Cleaning!$C:$C,0,0) -> 45843 | D2: =_xlfn.XLOOKUP(A2,Cleaning!$A:$A,Cleaning!$D:$D,0,0) -> 0.25981481 | E2: =_xlfn.XLOOKUP(A2,Cleaning!$A:$A,Cleaning!$E:$E,0,0) -> 45843 | F2: =_xlfn.XLOOKUP(A2,Cleaning!$A:$A,Cleaning!$F:$F,0,0) -> Saturday | G2: =_xlfn.XLOOKUP(A2,Cleaning!$A:$A,Cleaning!$G:$G,0,0) -> Breakfast | H2: =_xlfn.XLOOKUP(A2,Cleaning!$A:$A,Cleaning!$I:$I,0,0) -> Drive-Thru | I2: =_xlfn.XLOOKUP(A2,Cleaning!$A:$A,Cleaning!$J:$J,0,0) -> Bottled Water | J2: =_xlfn.XLOOKUP(A2,Cleaning!$A:$A,Cleaning!$L:$L,0,0) -> No Modifier | K2: =_xlfn.XLOOKUP(A2,Cleaning!$A:$A,Cleaning!$X:$X,0,0) -> Cash | L2: =_xlfn.XLOOKUP(A2,Cleaning!$A:$A,Cleaning!$M:$M,0,0) -> 1 | M2: =_xlfn.XLOOKUP(A2,Cleaning!$A:$A,Cleaning!$O:$O,0,0) -> 1.48 | N2: =_xlfn.XLOOKUP(A2,Cleaning!$A:$A,Cleaning!$P:$P,0,0) -> 1.48 | O2: =_xlfn.XLOOKUP(A2,Cleaning!$A:$A,Cleaning!$R:$R,0,0) -> 0.15 | P2: =_xlfn.XLOOKUP(A2,Cleaning!$A:$A,Cleaning!$T:$T,0,0) -> 0.1 | Q2: =_xlfn.XLOOKUP(A2,Cleaning!$A:$A,Cleaning!$V:$V,0,0) -> 1.43
A3: 120001 | B3: =_xlfn.XLOOKUP(A3,Cleaning!$A:$A,Cleaning!$B:$B,0,0) -> 201 | C3: =_xlfn.XLOOKUP(A3,Cleaning!$A:$A,Cleaning!$C:$C,0,0) -> 45843 | D3: =_xlfn.XLOOKUP(A3,Cleaning!$A:$A,Cleaning!$D:$D,0,0) -> 0.49225694 | E3: =_xlfn.XLOOKUP(A3,Cleaning!$A:$A,Cleaning!$E:$E,0,0) -> 45843 | F3: =_xlfn.XLOOKUP(A3,Cleaning!$A:$A,Cleaning!$F:$F,0,0) -> Saturday | G3: =_xlfn.XLOOKUP(A3,Cleaning!$A:$A,Cleaning!$G:$G,0,0) -> Lunch | H3: =_xlfn.XLOOKUP(A3,Cleaning!$A:$A,Cleaning!$I:$I,0,0) -> Dine-In | I3: =_xlfn.XLOOKUP(A3,Cleaning!$A:$A,Cleaning!$J:$J,0,0) -> Chicken Sandwich | J3: =_xlfn.XLOOKUP(A3,Cleaning!$A:$A,Cleaning!$L:$L,0,0) -> No Modifier | K3: =_xlfn.XLOOKUP(A3,Cleaning!$A:$A,Cleaning!$X:$X,0,0) -> Card | L3: =_xlfn.XLOOKUP(A3,Cleaning!$A:$A,Cleaning!$M:$M,0,0) -> 1 | M3: =_xlfn.XLOOKUP(A3,Cleaning!$A:$A,Cleaning!$O:$O,0,0) -> 5.34 | N3: =_xlfn.XLOOKUP(A3,Cleaning!$A:$A,Cleaning!$P:$P,0,0) -> 5.34 | O3: =_xlfn.XLOOKUP(A3,Cleaning!$A:$A,Cleaning!$R:$R,0,0) -> 0 | P3: =_xlfn.XLOOKUP(A3,Cleaning!$A:$A,Cleaning!$T:$T,0,0) -> 0.45 | Q3: =_xlfn.XLOOKUP(A3,Cleaning!$A:$A,Cleaning!$V:$V,0,0) -> 5.79
A4: 120002 | B4: =_xlfn.XLOOKUP(A4,Cleaning!$A:$A,Cleaning!$B:$B,0,0) -> 403 | C4: =_xlfn.XLOOKUP(A4,Cleaning!$A:$A,Cleaning!$C:$C,0,0) -> 45760 | D4: =_xlfn.XLOOKUP(A4,Cleaning!$A:$A,Cleaning!$D:$D,0,0) -> 0.33721065 | E4: =_xlfn.XLOOKUP(A4,Cleaning!$A:$A,Cleaning!$E:$E,0,0) -> 45760 | F4: =_xlfn.XLOOKUP(A4,Cleaning!$A:$A,Cleaning!$F:$F,0,0) -> Sunday | G4: =_xlfn.XLOOKUP(A4,Cleaning!$A:$A,Cleaning!$G:$G,0,0) -> Breakfast | H4: =_xlfn.XLOOKUP(A4,Cleaning!$A:$A,Cleaning!$I:$I,0,0) -> Takeout | I4: =_xlfn.XLOOKUP(A4,Cleaning!$A:$A,Cleaning!$J:$J,0,0) -> Bottled Water | J4: =_xlfn.XLOOKUP(A4,Cleaning!$A:$A,Cleaning!$L:$L,0,0) -> Light Ice | K4: =_xlfn.XLOOKUP(A4,Cleaning!$A:$A,Cleaning!$X:$X,0,0) -> Cash | L4: =_xlfn.XLOOKUP(A4,Cleaning!$A:$A,Cleaning!$M:$M,0,0) -> 1 | M4: =_xlfn.XLOOKUP(A4,Cleaning!$A:$A,Cleaning!$O:$O,0,0) -> 1.49 | N4: =_xlfn.XLOOKUP(A4,Cleaning!$A:$A,Cleaning!$P:$P,0,0) -> 1.49 | O4: =_xlfn.XLOOKUP(A4,Cleaning!$A:$A,Cleaning!$R:$R,0,0) -> 0.15 | P4: =_xlfn.XLOOKUP(A4,Cleaning!$A:$A,Cleaning!$T:$T,0,0) -> 0.1 | Q4: =_xlfn.XLOOKUP(A4,Cleaning!$A:$A,Cleaning!$V:$V,0,0) -> 1.44
A5: 120003 | B5: =_xlfn.XLOOKUP(A5,Cleaning!$A:$A,Cleaning!$B:$B,0,0) -> 301 | C5: =_xlfn.XLOOKUP(A5,Cleaning!$A:$A,Cleaning!$C:$C,0,0) -> 45833 | D5: =_xlfn.XLOOKUP(A5,Cleaning!$A:$A,Cleaning!$D:$D,0,0) -> 0.27936343 | E5: =_xlfn.XLOOKUP(A5,Cleaning!$A:$A,Cleaning!$E:$E,0,0) -> 45833 | F5: =_xlfn.XLOOKUP(A5,Cleaning!$A:$A,Cleaning!$F:$F,0,0) -> Wednesday | G5: =_xlfn.XLOOKUP(A5,Cleaning!$A:$A,Cleaning!$G:$G,0,0) -> Breakfast | H5: =_xlfn.XLOOKUP(A5,Cleaning!$A:$A,Cleaning!$I:$I,0,0) -> Drive-Thru | I5: =_xlfn.XLOOKUP(A5,Cleaning!$A:$A,Cleaning!$J:$J,0,0) -> Egg Muffin | J5: =_xlfn.XLOOKUP(A5,Cleaning!$A:$A,Cleaning!$L:$L,0,0) -> No Cheese | K5: =_xlfn.XLOOKUP(A5,Cleaning!$A:$A,Cleaning!$X:$X,0,0) -> Cash | L5: =_xlfn.XLOOKUP(A5,Cleaning!$A:$A,Cleaning!$M:$M,0,0) -> 1 | M5: =_xlfn.XLOOKUP(A5,Cleaning!$A:$A,Cleaning!$O:$O,0,0) -> 3.62 | N5: =_xlfn.XLOOKUP(A5,Cleaning!$A:$A,Cleaning!$P:$P,0,0) -> 3.62 | O5: =_xlfn.XLOOKUP(A5,Cleaning!$A:$A,Cleaning!$R:$R,0,0) -> 0 | P5: =_xlfn.XLOOKUP(A5,Cleaning!$A:$A,Cleaning!$T:$T,0,0) -> 0.34 | Q5: =_xlfn.XLOOKUP(A5,Cleaning!$A:$A,Cleaning!$V:$V,0,0) -> 3.96
A6: 120004 | B6: =_xlfn.XLOOKUP(A6,Cleaning!$A:$A,Cleaning!$B:$B,0,0) -> 301 | C6: =_xlfn.XLOOKUP(A6,Cleaning!$A:$A,Cleaning!$C:$C,0,0) -> 45870 | D6: =_xlfn.XLOOKUP(A6,Cleaning!$A:$A,Cleaning!$D:$D,0,0) -> 0.54069444 | E6: =_xlfn.XLOOKUP(A6,Cleaning!$A:$A,Cleaning!$E:$E,0,0) -> 45870 | F6: =_xlfn.XLOOKUP(A6,Cleaning!$A:$A,Cleaning!$F:$F,0,0) -> Friday | G6: =_xlfn.XLOOKUP(A6,Cleaning!$A:$A,Cleaning!$G:$G,0,0) -> Lunch | H6: =_xlfn.XLOOKUP(A6,Cleaning!$A:$A,Cleaning!$I:$I,0,0) -> Drive-Thru | I6: =_xlfn.XLOOKUP(A6,Cleaning!$A:$A,Cleaning!$J:$J,0,0) -> Spicy Chicken Combo | J6: =_xlfn.XLOOKUP(A6,Cleaning!$A:$A,Cleaning!$L:$L,0,0) -> No Modifier | K6: =_xlfn.XLOOKUP(A6,Cleaning!$A:$A,Cleaning!$X:$X,0,0) -> Card | L6: =_xlfn.XLOOKUP(A6,Cleaning!$A:$A,Cleaning!$M:$M,0,0) -> 2 | M6: =_xlfn.XLOOKUP(A6,Cleaning!$A:$A,Cleaning!$O:$O,0,0) -> 9.17 | N6: =_xlfn.XLOOKUP(A6,Cleaning!$A:$A,Cleaning!$P:$P,0,0) -> 18.34 | O6: =_xlfn.XLOOKUP(A6,Cleaning!$A:$A,Cleaning!$R:$R,0,0) -> 0 | P6: =_xlfn.XLOOKUP(A6,Cleaning!$A:$A,Cleaning!$T:$T,0,0) -> 1.38 | Q6: =_xlfn.XLOOKUP(A6,Cleaning!$A:$A,Cleaning!$V:$V,0,0) -> 19.72
A7: 120005 | B7: =_xlfn.XLOOKUP(A7,Cleaning!$A:$A,Cleaning!$B:$B,0,0) -> 501 | C7: =_xlfn.XLOOKUP(A7,Cleaning!$A:$A,Cleaning!$C:$C,0,0) -> 45850 | D7: =_xlfn.XLOOKUP(A7,Cleaning!$A:$A,Cleaning!$D:$D,0,0) -> 0.52258102 | E7: =_xlfn.XLOOKUP(A7,Cleaning!$A:$A,Cleaning!$E:$E,0,0) -> 45850 | F7: =_xlfn.XLOOKUP(A7,Cleaning!$A:$A,Cleaning!$F:$F,0,0) -> Saturday | G7: =_xlfn.XLOOKUP(A7,Cleaning!$A:$A,Cleaning!$G:$G,0,0) -> Lunch | H7: =_xlfn.XLOOKUP(A7,Cleaning!$A:$A,Cleaning!$I:$I,0,0) -> Dine-In | I7: =_xlfn.XLOOKUP(A7,Cleaning!$A:$A,Cleaning!$J:$J,0,0) -> Double Cheeseburger | J7: =_xlfn.XLOOKUP(A7,Cleaning!$A:$A,Cleaning!$L:$L,0,0) -> No Modifier | K7: =_xlfn.XLOOKUP(A7,Cleaning!$A:$A,Cleaning!$X:$X,0,0) -> Card | L7: =_xlfn.XLOOKUP(A7,Cleaning!$A:$A,Cleaning!$M:$M,0,0) -> 1 | M7: =_xlfn.XLOOKUP(A7,Cleaning!$A:$A,Cleaning!$O:$O,0,0) -> 5.64 | N7: =_xlfn.XLOOKUP(A7,Cleaning!$A:$A,Cleaning!$P:$P,0,0) -> 5.64 | O7: =_xlfn.XLOOKUP(A7,Cleaning!$A:$A,Cleaning!$R:$R,0,0) -> 0 | P7: =_xlfn.XLOOKUP(A7,Cleaning!$A:$A,Cleaning!$T:$T,0,0) -> 0.37 | Q7: =_xlfn.XLOOKUP(A7,Cleaning!$A:$A,Cleaning!$V:$V,0,0) -> 6.01
A8: 120006 | B8: =_xlfn.XLOOKUP(A8,Cleaning!$A:$A,Cleaning!$B:$B,0,0) -> 101 | C8: =_xlfn.XLOOKUP(A8,Cleaning!$A:$A,Cleaning!$C:$C,0,0) -> 45864 | D8: =_xlfn.XLOOKUP(A8,Cleaning!$A:$A,Cleaning!$D:$D,0,0) -> 0.24761574 | E8: =_xlfn.XLOOKUP(A8,Cleaning!$A:$A,Cleaning!$E:$E,0,0) -> 45864 | F8: =_xlfn.XLOOKUP(A8,Cleaning!$A:$A,Cleaning!$F:$F,0,0) -> Saturday | G8: =_xlfn.XLOOKUP(A8,Cleaning!$A:$A,Cleaning!$G:$G,0,0) -> Afternoon | H8: =_xlfn.XLOOKUP(A8,Cleaning!$A:$A,Cleaning!$I:$I,0,0) -> Delivery | I8: =_xlfn.XLOOKUP(A8,Cleaning!$A:$A,Cleaning!$J:$J,0,0) -> Onion Rings | J8: =_xlfn.XLOOKUP(A8,Cleaning!$A:$A,Cleaning!$L:$L,0,0) -> No Modifier | K8: =_xlfn.XLOOKUP(A8,Cleaning!$A:$A,Cleaning!$X:$X,0,0) -> MobilePay | L8: =_xlfn.XLOOKUP(A8,Cleaning!$A:$A,Cleaning!$M:$M,0,0) -> 1 | M8: =_xlfn.XLOOKUP(A8,Cleaning!$A:$A,Cleaning!$O:$O,0,0) -> 3.59 | N8: =_xlfn.XLOOKUP(A8,Cleaning!$A:$A,Cleaning!$P:$P,0,0) -> 3.59 | O8: =_xlfn.XLOOKUP(A8,Cleaning!$A:$A,Cleaning!$R:$R,0,0) -> 0.54 | P8: =_xlfn.XLOOKUP(A8,Cleaning!$A:$A,Cleaning!$T:$T,0,0) -> 0.29 | Q8: =_xlfn.XLOOKUP(A8,Cleaning!$A:$A,Cleaning!$V:$V,0,0) -> 3.34
A9: 120007 | B9: =_xlfn.XLOOKUP(A9,Cleaning!$A:$A,Cleaning!$B:$B,0,0) -> 403 | C9: =_xlfn.XLOOKUP(A9,Cleaning!$A:$A,Cleaning!$C:$C,0,0) -> 45859 | D9: =_xlfn.XLOOKUP(A9,Cleaning!$A:$A,Cleaning!$D:$D,0,0) -> 0.20011574 | E9: =_xlfn.XLOOKUP(A9,Cleaning!$A:$A,Cleaning!$E:$E,0,0) -> 45859 | F9: =_xlfn.XLOOKUP(A9,Cleaning!$A:$A,Cleaning!$F:$F,0,0) -> Monday | G9: =_xlfn.XLOOKUP(A9,Cleaning!$A:$A,Cleaning!$G:$G,0,0) -> Afternoon | H9: =_xlfn.XLOOKUP(A9,Cleaning!$A:$A,Cleaning!$I:$I,0,0) -> Takeout | I9: =_xlfn.XLOOKUP(A9,Cleaning!$A:$A,Cleaning!$J:$J,0,0) -> Soft Drink (Medium) | J9: =_xlfn.XLOOKUP(A9,Cleaning!$A:$A,Cleaning!$L:$L,0,0) -> No Modifier | K9: =_xlfn.XLOOKUP(A9,Cleaning!$A:$A,Cleaning!$X:$X,0,0) -> Cash | L9: =_xlfn.XLOOKUP(A9,Cleaning!$A:$A,Cleaning!$M:$M,0,0) -> 1 | M9: =_xlfn.XLOOKUP(A9,Cleaning!$A:$A,Cleaning!$O:$O,0,0) -> 1.8 | N9: =_xlfn.XLOOKUP(A9,Cleaning!$A:$A,Cleaning!$P:$P,0,0) -> 1.8 | O9: =_xlfn.XLOOKUP(A9,Cleaning!$A:$A,Cleaning!$R:$R,0,0) -> 0.27 | P9: =_xlfn.XLOOKUP(A9,Cleaning!$A:$A,Cleaning!$T:$T,0,0) -> 0.11 | Q9: =_xlfn.XLOOKUP(A9,Cleaning!$A:$A,Cleaning!$V:$V,0,0) -> 1.64
A10: 120008 | B10: =_xlfn.XLOOKUP(A10,Cleaning!$A:$A,Cleaning!$B:$B,0,0) -> 102 | C10: =_xlfn.XLOOKUP(A10,Cleaning!$A:$A,Cleaning!$C:$C,0,0) -> 45810 | D10: =_xlfn.XLOOKUP(A10,Cleaning!$A:$A,Cleaning!$D:$D,0,0) -> 0.464375 | E10: =_xlfn.XLOOKUP(A10,Cleaning!$A:$A,Cleaning!$E:$E,0,0) -> 45810 | F10: =_xlfn.XLOOKUP(A10,Cleaning!$A:$A,Cleaning!$F:$F,0,0) -> Monday | G10: =_xlfn.XLOOKUP(A10,Cleaning!$A:$A,Cleaning!$G:$G,0,0) -> Late Night | H10: =_xlfn.XLOOKUP(A10,Cleaning!$A:$A,Cleaning!$I:$I,0,0) -> Delivery | I10: =_xlfn.XLOOKUP(A10,Cleaning!$A:$A,Cleaning!$J:$J,0,0) -> Chicken Sandwich | J10: =_xlfn.XLOOKUP(A10,Cleaning!$A:$A,Cleaning!$L:$L,0,0) -> Extra Sauce | K10: =_xlfn.XLOOKUP(A10,Cleaning!$A:$A,Cleaning!$X:$X,0,0) -> Card | L10: =_xlfn.XLOOKUP(A10,Cleaning!$A:$A,Cleaning!$M:$M,0,0) -> 2 | M10: =_xlfn.XLOOKUP(A10,Cleaning!$A:$A,Cleaning!$O:$O,0,0) -> 5.47 | N10: =_xlfn.XLOOKUP(A10,Cleaning!$A:$A,Cleaning!$P:$P,0,0) -> 10.94 | O10: =_xlfn.XLOOKUP(A10,Cleaning!$A:$A,Cleaning!$R:$R,0,0) -> 0 | P10: =_xlfn.XLOOKUP(A10,Cleaning!$A:$A,Cleaning!$T:$T,0,0) -> 0.79 | Q10: =_xlfn.XLOOKUP(A10,Cleaning!$A:$A,Cleaning!$V:$V,0,0) -> 11.73
A11: 120009 | B11: =_xlfn.XLOOKUP(A11,Cleaning!$A:$A,Cleaning!$B:$B,0,0) -> 402 | C11: =_xlfn.XLOOKUP(A11,Cleaning!$A:$A,Cleaning!$C:$C,0,0) -> 45850 | D11: =_xlfn.XLOOKUP(A11,Cleaning!$A:$A,Cleaning!$D:$D,0,0) -> 0.22292824 | E11: =_xlfn.XLOOKUP(A11,Cleaning!$A:$A,Cleaning!$E:$E,0,0) -> 45850 | F11: =_xlfn.XLOOKUP(A11,Cleaning!$A:$A,Cleaning!$F:$F,0,0) -> Saturday | G11: =_xlfn.XLOOKUP(A11,Cleaning!$A:$A,Cleaning!$G:$G,0,0) -> Breakfast | H11: =_xlfn.XLOOKUP(A11,Cleaning!$A:$A,Cleaning!$I:$I,0,0) -> Drive-Thru | I11: =_xlfn.XLOOKUP(A11,Cleaning!$A:$A,Cleaning!$J:$J,0,0) -> Hash Browns | J11: =_xlfn.XLOOKUP(A11,Cleaning!$A:$A,Cleaning!$L:$L,0,0) -> No Modifier | K11: =_xlfn.XLOOKUP(A11,Cleaning!$A:$A,Cleaning!$X:$X,0,0) -> Card | L11: =_xlfn.XLOOKUP(A11,Cleaning!$A:$A,Cleaning!$M:$M,0,0) -> 1 | M11: =_xlfn.XLOOKUP(A11,Cleaning!$A:$A,Cleaning!$O:$O,0,0) -> 2 | N11: =_xlfn.XLOOKUP(A11,Cleaning!$A:$A,Cleaning!$P:$P,0,0) -> 2 | O11: =_xlfn.XLOOKUP(A11,Cleaning!$A:$A,Cleaning!$R:$R,0,0) -> 0 | P11: =_xlfn.XLOOKUP(A11,Cleaning!$A:$A,Cleaning!$T:$T,0,0) -> 0.12 | Q11: =_xlfn.XLOOKUP(A11,Cleaning!$A:$A,Cleaning!$V:$V,0,0) -> 2.12
A12: 120010 | B12: =_xlfn.XLOOKUP(A12,Cleaning!$A:$A,Cleaning!$B:$B,0,0) -> 103 | C12: =_xlfn.XLOOKUP(A12,Cleaning!$A:$A,Cleaning!$C:$C,0,0) -> 45766 | D12: =_xlfn.XLOOKUP(A12,Cleaning!$A:$A,Cleaning!$D:$D,0,0) -> 0.38599537 | E12: =_xlfn.XLOOKUP(A12,Cleaning!$A:$A,Cleaning!$E:$E,0,0) -> 45766 | F12: =_xlfn.XLOOKUP(A12,Cleaning!$A:$A,Cleaning!$F:$F,0,0) -> Saturday | G12: =_xlfn.XLOOKUP(A12,Cleaning!$A:$A,Cleaning!$G:$G,0,0) -> Dinner | H12: =_xlfn.XLOOKUP(A12,Cleaning!$A:$A,Cleaning!$I:$I,0,0) -> Takeout | I12: =_xlfn.XLOOKUP(A12,Cleaning!$A:$A,Cleaning!$J:$J,0,0) -> Double Cheeseburger | J12: =_xlfn.XLOOKUP(A12,Cleaning!$A:$A,Cleaning!$L:$L,0,0) -> No Modifier | K12: =_xlfn.XLOOKUP(A12,Cleaning!$A:$A,Cleaning!$X:$X,0,0) -> Card | L12: =_xlfn.XLOOKUP(A12,Cleaning!$A:$A,Cleaning!$M:$M,0,0) -> 1 | M12: =_xlfn.XLOOKUP(A12,Cleaning!$A:$A,Cleaning!$O:$O,0,0) -> 5.55 | N12: =_xlfn.XLOOKUP(A12,Cleaning!$A:$A,Cleaning!$P:$P,0,0) -> 5.55 | O12: =_xlfn.XLOOKUP(A12,Cleaning!$A:$A,Cleaning!$R:$R,0,0) -> 0 | P12: =_xlfn.XLOOKUP(A12,Cleaning!$A:$A,Cleaning!$T:$T,0,0) -> 0.33 | Q12: =_xlfn.XLOOKUP(A12,Cleaning!$A:$A,Cleaning!$V:$V,0,0) -> 5.88
A13: 120011 | B13: =_xlfn.XLOOKUP(A13,Cleaning!$A:$A,Cleaning!$B:$B,0,0) -> 102 | C13: =_xlfn.XLOOKUP(A13,Cleaning!$A:$A,Cleaning!$C:$C,0,0) -> 45854 | D13: =_xlfn.XLOOKUP(A13,Cleaning!$A:$A,Cleaning!$D:$D,0,0) -> 0.46420139 | E13: =_xlfn.XLOOKUP(A13,Cleaning!$A:$A,Cleaning!$E:$E,0,0) -> 45854 | F13: =_xlfn.XLOOKUP(A13,Cleaning!$A:$A,Cleaning!$F:$F,0,0) -> Wednesday | G13: =_xlfn.XLOOKUP(A13,Cleaning!$A:$A,Cleaning!$G:$G,0,0) -> Morning | H13: =_xlfn.XLOOKUP(A13,Cleaning!$A:$A,Cleaning!$I:$I,0,0) -> Dine-In | I13: =_xlfn.XLOOKUP(A13,Cleaning!$A:$A,Cleaning!$J:$J,0,0) -> Apple Pie | J13: =_xlfn.XLOOKUP(A13,Cleaning!$A:$A,Cleaning!$L:$L,0,0) -> No Modifier | K13: =_xlfn.XLOOKUP(A13,Cleaning!$A:$A,Cleaning!$X:$X,0,0) -> Card | L13: =_xlfn.XLOOKUP(A13,Cleaning!$A:$A,Cleaning!$M:$M,0,0) -> 1 | M13: =_xlfn.XLOOKUP(A13,Cleaning!$A:$A,Cleaning!$O:$O,0,0) -> 1.53 | N13: =_xlfn.XLOOKUP(A13,Cleaning!$A:$A,Cleaning!$P:$P,0,0) -> 1.53 | O13: =_xlfn.XLOOKUP(A13,Cleaning!$A:$A,Cleaning!$R:$R,0,0) -> 0 | P13: =_xlfn.XLOOKUP(A13,Cleaning!$A:$A,Cleaning!$T:$T,0,0) -> 0.1 | Q13: =_xlfn.XLOOKUP(A13,Cleaning!$A:$A,Cleaning!$V:$V,0,0) -> 1.63
... A1744: 121742 | B1744: =_xlfn.XLOOKUP(A1744,Cleaning!$A:$A,Cleaning!$B:$B,0,0) -> 301 | C1744: =_xlfn.XLOOKUP(A1744,Cleaning!$A:$A,Cleaning!$C:$C,0,0) -> 45767 | D1744: =_xlfn.XLOOKUP(A1744,Cleaning!$A:$A,Cleaning!$D:$D,0,0) -> 0.4678125 | E1744: =_xlfn.XLOOKUP(A1744,Cleaning!$A:$A,Cleaning!$E:$E,0,0) -> 45767 | F1744: =_xlfn.XLOOKUP(A1744,Cleaning!$A:$A,Cleaning!$F:$F,0,0) -> Sunday | G1744: =_xlfn.XLOOKUP(A1744,Cleaning!$A:$A,Cleaning!$G:$G,0,0) -> Lunch | H1744: =_xlfn.XLOOKUP(A1744,Cleaning!$A:$A,Cleaning!$I:$I,0,0) -> Drive-Thru | I1744: =_xlfn.XLOOKUP(A1744,Cleaning!$A:$A,Cleaning!$J:$J,0,0) -> Soft Drink (Medium) | J1744: =_xlfn.XLOOKUP(A1744,Cleaning!$A:$A,Cleaning!$L:$L,0,0) -> Light Ice | K1744: =_xlfn.XLOOKUP(A1744,Cleaning!$A:$A,Cleaning!$X:$X,0,0) -> MobilePay | L1744: =_xlfn.XLOOKUP(A1744,Cleaning!$A:$A,Cleaning!$M:$M,0,0) -> 3 | M1744: =_xlfn.XLOOKUP(A1744,Cleaning!$A:$A,Cleaning!$O:$O,0,0) -> 1.75 | N1744: =_xlfn.XLOOKUP(A1744,Cleaning!$A:$A,Cleaning!$P:$P,0,0) -> 5.25 | O1744: =_xlfn.XLOOKUP(A1744,Cleaning!$A:$A,Cleaning!$R:$R,0,0) -> 0 | P1744: =_xlfn.XLOOKUP(A1744,Cleaning!$A:$A,Cleaning!$T:$T,0,0) -> 0.37 | Q1744: =_xlfn.XLOOKUP(A1744,Cleaning!$A:$A,Cleaning!$V:$V,0,0) -> 5.62

Sheet Pivot_Table
A1: Menu_Item | B1: (All) | E1: Service_Mode | F1: Sum of Quantity
E2: Delivery | F2: 303
A3: Count of Order_ID | B3: Sum of Total_Amount | E3: Dine-In | F3: 662
A4: 1743 | B4: 11641.64 | E4: Drive-Thru | F4: 641
E5: Takeout | F5: 591
E6: Unknown | F6: 17
A7: Quantity | B7: Sum of Total_Amount | C7: Count of Order_ID | E7: Grand Total | F7: 2214
A8: 1 | B8: 7441.64 | C8: 1360
A9: 2 | B9: 3010.23 | C9: 304
A10: 3 | B10: 1050.76 | C10: 70
A11: 4 | B11: 139.01 | C11: 9
A12: Grand Total | B12: 11641.64 | C12: 1743
A15: Payment_Type | B15: Average of Total_Amount
A16: Card | B16: 6.9383749
A17: Cash | B17: 6.2048276
A18: GiftCard | B18: 7.0902198
A19: MobilePay | B19: 6.2427206
